Workbook

Sheet Original Dataset
A1: store_id | B1: month | C1: region | D1: store_type | E1: marketing_spend | F1: footfall | G1: avg_discount_pct | H1: staff_count | I1: inventory_availability_pct | J1: competitor_distance_km | K1: holiday_flag | L1: customer_rating | M1: monthly_sales | N1: monthly_profit
A2: STR-1001 | B2: 45658 | C2: East | D2: Residential | E2: 70389.11 | F2: 8302 | G2: 0.042 | H2: 17 | I2: 75 | J2: 5.28 | K2: 1 | L2: 3.1 | M2: 658832.62 | N2: 84349.93
A3: STR-1001 | B3: 45689 | C3: East | D3: Residential | E3: 43827.89 | F3: 8487 | G3: 0.168 | H3: 23 | I3: 84.4 | J3: 4.31 | K3: 0 | L3: 2.8 | M3: 634436 | N3: 106130.54
A4: STR-1001 | B4: 45717 | C4: East | D4: Residential | E4: 59921.75 | F4: 9113 | G4: 0.133 | H4: 20 | I4: 88 | J4: 12 | K4: 0 | L4: 3.2 | M4: 678722.06 | N4: 101883.86
A5: STR-1001 | B5: 45748 | C5: East | D5: Residential | E5: 56856.63 | F5: 9431 | G5: 0.142 | H5: 23 | I5: 86.9 | J5: 4.97 | K5: 0 | L5: 3.4 | M5: 658920.3 | N5: 97910.37
A6: STR-1002 | B6: 45658 | C6: East | D6: High Street | E6: 48412.64 | F6: 9545 | G6: 0.231 | H6: 21 | I6: 97.6 | J6: 6.94 | K6: 1 | L6: 4.2 | M6: 741341.44 | N6: 119208.17
A7: STR-1002 | B7: 45689 | C7: East | D7: High Street | E7: 64811.21 | F7: 9792 | G7: 0.112 | H7: 20 | I7: 84.2 | J7: 2.88 | K7: 0 | L7: 4.2 | M7: 761835.34 | N7: 149602.23
A8: STR-1002 | B8: 45717 | C8: East | D8: High Street | E8: 46213.45 | F8: 10616 | G8: 0.122 | H8: 22 | I8: 85.2 | J8: 0.2 | K8: 1 | L8: 4.1 | M8: 806615.54 | N8: 131364.62
A9: STR-1002 | B9: 45748 | C9: East | D9: High Street | E9: 68148.52 | F9: 8567 | G9: 0.127 | H9: 23 | I9: 95.6 | J9: 0.8 | K9: 0 | L9: 3.9 | M9: 850164.26 | N9: 149262.75
A10: STR-1003 | B10: 45658 | C10: North | D10: Airport | E10: 71838.86 | F10: 10979 | G10: 0.215 | H10: 26 | I10: 88.6 | J10: 7.7 | K10: 1 | L10: 3.8 | M10: 930581.7 | N10: 136207.98
A11: STR-1003 | B11: 45689 | C11: North | D11: Airport | E11: 68133.44 | F11: 9459 | G11: 0.22 | H11: 21 | I11: 85 | J11: 1.91 | K11: 0 | L11: 4.2 | M11: 779010.94 | N11: 106328.09
A12: STR-1003 | B12: 45717 | C12: North | D12: Airport | E12: 34285.21 | F12: 9172 | G12: 0.213 | H12: 22 | I12: 88.3 | J12: 10.46 | K12: 1 | L12: 3.8 | M12: 723060.76 | N12: 123131.24
A13: STR-1003 | B13: 45748 | C13: North | D13: Airport | E13: 67979.88 | F13: 11230 | G13: 0.002 | H13: 28 | I13: 85.3 | J13: 7.16 | K13: 0 | L13: 3.8 | M13: 910791.94 | N13: 158891.28
... A34: STR-1009 | B34: 45658 | C34: North | D34: Residential | E34: 54597.83 | F34: 9429 | G34: 0.188 | H34: 21 | I34: 83.3 | J34: 11.71 | K34: 0 | L34: 4.2 | M34: 641865.03 | N34: 81342.58
A35: STR-1009 | B35: 45689 | C35: North | D35: Residential | E35: 73771.91 | F35: 11695 | G35: 0.07 | H35: 25 | I35: 84.7 | J35: 0.62 | K35: 0 | M35: 799477.76 | N35: 164974.41
A36: STR-1009 | B36: 45717 | C36: North | D36: Residential | E36: 74413.88 | F36: 9449 | G36: 0.039 | H36: 23 | I36: 92.1 | J36: 2.12 | K36: 0 | L36: 3.5 | M36: 798952.17 | N36: 161499.04
A37: STR-1009 | B37: 45748 | C37: North | D37: Residential | E37: 52483.77 | F37: 10453 | G37: 0.247 | H37: 25 | I37: 99 | J37: 6.31 | K37: 0 | L37: 3.6 | M37: 800979.78 | N37: 149242.27
A38: STR-1010 | B38: 45658 | C38: North | D38: Mall | E38: 75269.87 | F38: 8838 | G38: 0.092 | H38: 21 | I38: 83.1 | J38: 9.56 | K38: 1 | L38: 4.2 | M38: 820593.93 | N38: 115860.06
A39: STR-1010 | B39: 45689 | C39: North | D39: Mall | E39: 61245.41 | F39: 8156 | G39: 0.156 | H39: 19 | I39: 92.9 | J39: 9.05 | K39: 0 | L39: 3.8 | M39: 718330.53 | N39: 93247.9
A40: STR-1010 | B40: 45717 | C40: North | D40: Mall | E40: 93381.26 | F40: 7562 | G40: 0.198 | H40: 19 | I40: 82.9 | J40: 5.05 | K40: 0 | L40: 4 | M40: 736633.4 | N40: 115654.66
A41: STR-1010 | B41: 45748 | C41: North | D41: Mall | E41: 65012.19 | F41: 9598 | G41: 0.085 | H41: 24 | I41: 98.3 | J41: 0.89 | K41: 0 | L41: 3.8 | M41: 828623.85 | N41: 167320.52
A42: STR-1011 | B42: 45658 | C42: East | D42: Mall | E42: 40462.94 | F42: 3660 | G42: 0.218 | H42: 11 | I42: 95.2 | J42: 5.57 | K42: 0 | L42: 4.4 | M42: 592195.85 | N42: 92291.56
A43: STR-1011 | B43: 45689 | C43: East | D43: Mall | E43: 46123.88 | F43: 3227 | G43: 0.143 | H43: 10 | I43: 75.4 | J43: 1.06 | K43: 0 | L43: 4.4 | M43: 532644.46 | N43: 60681.32
A44: STR-1011 | B44: 45717 | C44: East | D44: Mall | E44: 68077.54 | F44: 3360 | G44: 0.128 | H44: 14 | I44: 88.2 | J44: 1.24 | K44: 1 | L44: 4 | M44: 657429.18 | N44: 88919.74
A45: STR-1011 | B45: 45748 | C45: East | D45: Mall | E45: 64882.14 | F45: 3642 | G45: 0.019 | H45: 13 | I45: 87.8 | J45: 4.52 | K45: 0 | L45: 4.2 | M45: 605178 | N45: 106958.74
A46: STR-1012 | B46: 45658 | C46: West | D46: Residential | E46: 138855.51 | F46: 5145 | G46: 0.06 | H46: 17 | I46: 88.2 | J46: 9.58 | K46: 0 | L46: 3.2 | M46: 595467.6 | N46: 104276.46
A47: STR-1012 | B47: 45689 | C47: West | D47: Residential | E47: 63630.21 | F47: 4460 | G47: 0.235 | H47: 14 | I47: 98.6 | J47: 5.52 | K47: 0 | L47: 3.5 | M47: 599603.4 | N47: 112685.12
... A72: STR-1018 | B72: 45717 | C72: East | D72: High Street | E72: 60571.82 | F72: 3193 | G72: 0.197 | H72: 7 | I72: 99 | J72: 1.43 | K72: 0 | L72: 3.2 | M72: 605023.87 | N72: 98545.81
A73: STR-1018 | B73: 45748 | C73: East | D73: High Street | E73: 55081.16 | F73: 5485 | G73: 0.036 | H73: 12 | I73: 88 | K73: 0 | L73: 3.5 | M73: 674774.09 | N73: 141917.59
A74: STR-1019 | B74: 45658 | C74: East | D74: Residential | E74: 46201.46 | F74: 5918 | G74: 0.277 | H74: 13 | I74: 78.8 | J74: 4.91 | K74: 0 | L74: 4.5 | M74: 616069.41 | N74: 54453.99
A75: STR-1019 | B75: 45689 | C75: East | D75: Residential | E75: 53762.92 | F75: 6821 | G75: 0.066 | H75: 19 | I75: 94.6 | J75: 7.03 | K75: 0 | L75: 4.4 | M75: 630829.94 | N75: 117090.02
A76: STR-1019 | B76: 45717 | C76: East | D76: Residential | E76: 70144.78 | F76: 6806 | G76: 0.178 | H76: 20 | I76: 93.1 | J76: 0.28 | K76: 1 | L76: 4.3 | M76: 788087.68 | N76: 116803.42
A77: STR-1019 | B77: 45748 | C77: East | D77: Residential | E77: 58749.63 | F77: 8252 | G77: 0.203 | H77: 20 | I77: 85.2 | J77: 3.61 | K77: 0 | L77: 4.5 | M77: 680840.36 | N77: 68007.68
A78: STR-1020 | B78: 45658 | C78: South | D78: High Street | E78: 56973.18 | F78: 6662 | G78: 0.1 | H78: 15 | I78: 77.7 | J78: 7.52 | K78: 1 | L78: 3.2 | M78: 643657.47 | N78: 87022.45
A79: STR-1020 | B79: 45689 | C79: South | D79: High Street | E79: 54872.82 | F79: 5962 | G79: 0.064 | H79: 12 | I79: 85.4 | J79: 2.58 | K79: 0 | L79: 2.9 | M79: 691112.6 | N79: 109212.83
A80: STR-1020 | B80: 45717 | C80: South | D80: High Street | E80: 80562.81 | F80: 7470 | G80: 0.172 | H80: 16 | I80: 83.5 | J80: 2.29 | K80: 0 | L80: 3.3 | M80: 776922.17 | N80: 150701.93
A81: STR-1020 | B81: 45748 | C81: South | D81: High Street | E81: 77999.9 | F81: 5974 | G81: 0.252 | H81: 14 | I81: 81.3 | J81: 2.39 | K81: 0 | L81: 3.2 | M81: 636561.34 | N81: 93861.06
A82: STR-1021 | B82: 45658 | C82: West | D82: Mall | E82: 60881.01 | F82: 5410 | G82: 0.179 | H82: 15 | I82: 83.9 | J82: 5.24 | K82: 0 | L82: 4.6 | M82: 621369.58 | N82: 85493.64
A83: STR-1021 | B83: 45689 | C83: West | D83: Mall | E83: 60628.38 | F83: 4451 | G83: 0.095 | H83: 10 | I83: 89.6 | J83: 3.17 | K83: 0 | L83: 4.6 | M83: 682208.01 | N83: 110318.84
A84: STR-1021 | B84: 45717 | C84: West | D84: Mall | E84: 72731.14 | F84: 4644 | G84: 0.084 | H84: 15 | I84: 87.1 | J84: 2.66 | K84: 0 | L84: 4.6 | M84: 727241.86 | N84: 155810.3
...

Sheet Cleaned Data
A1: store_id | B1: month | C1: region | D1: store_type | E1: marketing_spend | F1: footfall | G1: avg_discount_pct | H1: staff_count | I1: inventory_availability_pct | J1: competitor_distance_km | K1: holiday_flag | L1: customer_rating | M1: monthly_sales | N1: monthly_profit
A2: STR-1001 | B2: 45658 | C2: East | D2: Residential | E2: 70389.11 | F2: 8302 | G2: 0.042 | H2: 17 | I2: 75 | J2: =IF(ISBLANK('Original Dataset'!J2),$Z$2,'Original Dataset'!J2) -> 5.28 | K2: 1 | L2: =IF(ISBLANK('Original Dataset'!L2),$Z$3,'Original Dataset'!L2) -> 3.1 | M2: 658832.62 | N2: 84349.93 | Z2: =MEDIAN('Original Dataset'!J:J) -> 3.365
A3: STR-1001 | B3: 45689 | C3: East | D3: Residential | E3: 43827.89 | F3: 8487 | G3: 0.168 | H3: 23 | I3: 84.4 | J3: =IF(ISBLANK('Original Dataset'!J3),$Z$2,'Original Dataset'!J3) -> 4.31 | K3: 0 | L3: =IF(ISBLANK('Original Dataset'!L3),$Z$3,'Original Dataset'!L3) -> 2.8 | M3: 634436 | N3: 106130.54 | Z3: =AVERAGE('Original Dataset'!L:L) -> 3.9246795
A4: STR-1001 | B4: 45717 | C4: East | D4: Residential | E4: 59921.75 | F4: 9113 | G4: 0.133 | H4: 20 | I4: 88 | J4: =IF(ISBLANK('Original Dataset'!J4),$Z$2,'Original Dataset'!J4) -> 12 | K4: 0 | L4: =IF(ISBLANK('Original Dataset'!L4),$Z$3,'Original Dataset'!L4) -> 3.2 | M4: 678722.06 | N4: 101883.86
A5: STR-1001 | B5: 45748 | C5: East | D5: Residential | E5: 56856.63 | F5: 9431 | G5: 0.142 | H5: 23 | I5: 86.9 | J5: =IF(ISBLANK('Original Dataset'!J5),$Z$2,'Original Dataset'!J5) -> 4.97 | K5: 0 | L5: =IF(ISBLANK('Original Dataset'!L5),$Z$3,'Original Dataset'!L5) -> 3.4 | M5: 658920.3 | N5: 97910.37
A6: STR-1002 | B6: 45658 | C6: East | D6: High Street | E6: 48412.64 | F6: 9545 | G6: 0.231 | H6: 21 | I6: 97.6 | J6: =IF(ISBLANK('Original Dataset'!J6),$Z$2,'Original Dataset'!J6) -> 6.94 | K6: 1 | L6: =IF(ISBLANK('Original Dataset'!L6),$Z$3,'Original Dataset'!L6) -> 4.2 | M6: 741341.44 | N6: 119208.17
A7: STR-1002 | B7: 45689 | C7: East | D7: High Street | E7: 64811.21 | F7: 9792 | G7: 0.112 | H7: 20 | I7: 84.2 | J7: =IF(ISBLANK('Original Dataset'!J7),$Z$2,'Original Dataset'!J7) -> 2.88 | K7: 0 | L7: =IF(ISBLANK('Original Dataset'!L7),$Z$3,'Original Dataset'!L7) -> 4.2 | M7: 761835.34 | N7: 149602.23
A8: STR-1002 | B8: 45717 | C8: East | D8: High Street | E8: 46213.45 | F8: 10616 | G8: 0.122 | H8: 22 | I8: 85.2 | J8: =IF(ISBLANK('Original Dataset'!J8),$Z$2,'Original Dataset'!J8) -> 0.2 | K8: 1 | L8: =IF(ISBLANK('Original Dataset'!L8),$Z$3,'Original Dataset'!L8) -> 4.1 | M8: 806615.54 | N8: 131364.62
A9: STR-1002 | B9: 45748 | C9: East | D9: High Street | E9: 68148.52 | F9: 8567 | G9: 0.127 | H9: 23 | I9: 95.6 | J9: =IF(ISBLANK('Original Dataset'!J9),$Z$2,'Original Dataset'!J9) -> 0.8 | K9: 0 | L9: =IF(ISBLANK('Original Dataset'!L9),$Z$3,'Original Dataset'!L9) -> 3.9 | M9: 850164.26 | N9: 149262.75
A10: STR-1003 | B10: 45658 | C10: North | D10: Airport | E10: 71838.86 | F10: 10979 | G10: 0.215 | H10: 26 | I10: 88.6 | J10: =IF(ISBLANK('Original Dataset'!J10),$Z$2,'Original Dataset'!J10) -> 7.7 | K10: 1 | L10: =IF(ISBLANK('Original Dataset'!L10),$Z$3,'Original Dataset'!L10) -> 3.8 | M10: 930581.7 | N10: 136207.98
A11: STR-1003 | B11: 45689 | C11: North | D11: Airport | E11: 68133.44 | F11: 9459 | G11: 0.22 | H11: 21 | I11: 85 | J11: =IF(ISBLANK('Original Dataset'!J11),$Z$2,'Original Dataset'!J11) -> 1.91 | K11: 0 | L11: =IF(ISBLANK('Original Dataset'!L11),$Z$3,'Original Dataset'!L11) -> 4.2 | M11: 779010.94 | N11: 106328.09
A12: STR-1003 | B12: 45717 | C12: North | D12: Airport | E12: 34285.21 | F12: 9172 | G12: 0.213 | H12: 22 | I12: 88.3 | J12: =IF(ISBLANK('Original Dataset'!J12),$Z$2,'Original Dataset'!J12) -> 10.46 | K12: 1 | L12: =IF(ISBLANK('Original Dataset'!L12),$Z$3,'Original Dataset'!L12) -> 3.8 | M12: 723060.76 | N12: 123131.24
A13: STR-1003 | B13: 45748 | C13: North | D13: Airport | E13: 67979.88 | F13: 11230 | G13: 0.002 | H13: 28 | I13: 85.3 | J13: =IF(ISBLANK('Original Dataset'!J13),$Z$2,'Original Dataset'!J13) -> 7.16 | K13: 0 | L13: =IF(ISBLANK('Original Dataset'!L13),$Z$3,'Original Dataset'!L13) -> 3.8 | M13: 910791.94 | N13: 158891.28
A14: STR-1004 | B14: 45658 | C14: East | D14: Residential | E14: 71828.26 | F14: 12775 | G14: 0.116 | H14: 30 | I14: 81.7 | J14: =IF(ISBLANK('Original Dataset'!J14),$Z$2,'Original Dataset'!J14) -> 4.24 | K14: 1 | L14: =IF(ISBLANK('Original Dataset'!L14),$Z$3,'Original Dataset'!L14) -> 4.2 | M14: 922168.6 | N14: 107494.53
A15: STR-1004 | B15: 45689 | C15: East | D15: Residential | E15: 55716.82 | F15: 10054 | G15: 0.146 | H15: 24 | I15: 84.9 | J15: =IF(ISBLANK('Original Dataset'!J15),$Z$2,'Original Dataset'!J15) -> 1.06 | K15: 0 | L15: =IF(ISBLANK('Original Dataset'!L15),$Z$3,'Original Dataset'!L15) -> 4.3 | M15: 726606.28 | N15: 122729.29
... A321: STR-1080 | B321: 45748 | C321: East | D321: Residential | E321: 40553.11 | F321: 5317 | G321: 0.165 | H321: 17 | I321: 84.3 | J321: =IF(ISBLANK('Original Dataset'!J321),$Z$2,'Original Dataset'!J321) -> 11.82 | K321: 0 | L321: =IF(ISBLANK('Original Dataset'!L321),$Z$3,'Original Dataset'!L321) -> 4.1 | M321: 559660.84 | N321: 71443.61

Sheet Dummy Variables
A1: store_id | B1: month | C1: region | D1: store_type | E1: marketing_spend | F1: footfall | G1: avg_discount_pct | H1: staff_count | I1: inventory_availability_pct | J1: competitor_distance_km | K1: holiday_flag | L1: customer_rating | M1: monthly_sales | N1: monthly_profit | O1: Region_North | P1: Region_South | Q1: Region_East | R1: Store_Mall | S1: Store_HighStreet | T1: Store_Airport
A2: STR-1001 | B2: 45658 | C2: East | D2: Residential | E2: 70389.11 | F2: 8302 | G2: 0.042 | H2: 17 | I2: 75 | J2: 5.28 | K2: 1 | L2: 3.1 | M2: 658832.62 | N2: 84349.93 | O2: =IF(C2="North",1,0) -> 0 | P2: =IF(C2="South",1,0) -> 0 | Q2: =IF(C2="East",1,0) -> 1 | R2: =IF(D2="Mall",1,0) -> 0 | S2: =IF(D2="High Street",1,0) -> 0 | T2: =IF(D2="Airport",1,0) -> 0
A3: STR-1001 | B3: 45689 | C3: East | D3: Residential | E3: 43827.89 | F3: 8487 | G3: 0.168 | H3: 23 | I3: 84.4 | J3: 4.31 | K3: 0 | L3: 2.8 | M3: 634436 | N3: 106130.54 | O3: =IF(C3="North",1,0) -> 0 | P3: =IF(C3="South",1,0) -> 0 | Q3: =IF(C3="East",1,0) -> 1 | R3: =IF(D3="Mall",1,0) -> 0 | S3: =IF(D3="High Street",1,0) -> 0 | T3: =IF(D3="Airport",1,0) -> 0
A4: STR-1001 | B4: 45717 | C4: East | D4: Residential | E4: 59921.75 | F4: 9113 | G4: 0.133 | H4: 20 | I4: 88 | J4: 12 | K4: 0 | L4: 3.2 | M4: 678722.06 | N4: 101883.86 | O4: =IF(C4="North",1,0) -> 0 | P4: =IF(C4="South",1,0) -> 0 | Q4: =IF(C4="East",1,0) -> 1 | R4: =IF(D4="Mall",1,0) -> 0 | S4: =IF(D4="High Street",1,0) -> 0 | T4: =IF(D4="Airport",1,0) -> 0
A5: STR-1001 | B5: 45748 | C5: East | D5: Residential | E5: 56856.63 | F5: 9431 | G5: 0.142 | H5: 23 | I5: 86.9 | J5: 4.97 | K5: 0 | L5: 3.4 | M5: 658920.3 | N5: 97910.37 | O5: =IF(C5="North",1,0) -> 0 | P5: =IF(C5="South",1,0) -> 0 | Q5: =IF(C5="East",1,0) -> 1 | R5: =IF(D5="Mall",1,0) -> 0 | S5: =IF(D5="High Street",1,0) -> 0 | T5: =IF(D5="Airport",1,0) -> 0
A6: STR-1002 | B6: 45658 | C6: East | D6: High Street | E6: 48412.64 | F6: 9545 | G6: 0.231 | H6: 21 | I6: 97.6 | J6: 6.94 | K6: 1 | L6: 4.2 | M6: 741341.44 | N6: 119208.17 | O6: =IF(C6="North",1,0) -> 0 | P6: =IF(C6="South",1,0) -> 0 | Q6: =IF(C6="East",1,0) -> 1 | R6: =IF(D6="Mall",1,0) -> 0 | S6: =IF(D6="High Street",1,0) -> 1 | T6: =IF(D6="Airport",1,0) -> 0
A7: STR-1002 | B7: 45689 | C7: East | D7: High Street | E7: 64811.21 | F7: 9792 | G7: 0.112 | H7: 20 | I7: 84.2 | J7: 2.88 | K7: 0 | L7: 4.2 | M7: 761835.34 | N7: 149602.23 | O7: =IF(C7="North",1,0) -> 0 | P7: =IF(C7="South",1,0) -> 0 | Q7: =IF(C7="East",1,0) -> 1 | R7: =IF(D7="Mall",1,0) -> 0 | S7: =IF(D7="High Street",1,0) -> 1 | T7: =IF(D7="Airport",1,0) -> 0
A8: STR-1002 | B8: 45717 | C8: East | D8: High Street | E8: 46213.45 | F8: 10616 | G8: 0.122 | H8: 22 | I8: 85.2 | J8: 0.2 | K8: 1 | L8: 4.1 | M8: 806615.54 | N8: 131364.62 | O8: =IF(C8="North",1,0) -> 0 | P8: =IF(C8="South",1,0) -> 0 | Q8: =IF(C8="East",1,0) -> 1 | R8: =IF(D8="Mall",1,0) -> 0 | S8: =IF(D8="High Street",1,0) -> 1 | T8: =IF(D8="Airport",1,0) -> 0
A9: STR-1002 | B9: 45748 | C9: East | D9: High Street | E9: 68148.52 | F9: 8567 | G9: 0.127 | H9: 23 | I9: 95.6 | J9: 0.8 | K9: 0 | L9: 3.9 | M9: 850164.26 | N9: 149262.75 | O9: =IF(C9="North",1,0) -> 0 | P9: =IF(C9="South",1,0) -> 0 | Q9: =IF(C9="East",1,0) -> 1 | R9: =IF(D9="Mall",1,0) -> 0 | S9: =IF(D9="High Street",1,0) -> 1 | T9: =IF(D9="Airport",1,0) -> 0
A10: STR-1003 | B10: 45658 | C10: North | D10: Airport | E10: 71838.86 | F10: 10979 | G10: 0.215 | H10: 26 | I10: 88.6 | J10: 7.7 | K10: 1 | L10: 3.8 | M10: 930581.7 | N10: 136207.98 | O10: =IF(C10="North",1,0) -> 1 | P10: =IF(C10="South",1,0) -> 0 | Q10: =IF(C10="East",1,0) -> 0 | R10: =IF(D10="Mall",1,0) -> 0 | S10: =IF(D10="High Street",1,0) -> 0 | T10: =IF(D10="Airport",1,0) -> 1
A11: STR-1003 | B11: 45689 | C11: North | D11: Airport | E11: 68133.44 | F11: 9459 | G11: 0.22 | H11: 21 | I11: 85 | J11: 1.91 | K11: 0 | L11: 4.2 | M11: 779010.94 | N11: 106328.09 | O11: =IF(C11="North",1,0) -> 1 | P11: =IF(C11="South",1,0) -> 0 | Q11: =IF(C11="East",1,0) -> 0 | R11: =IF(D11="Mall",1,0) -> 0 | S11: =IF(D11="High Street",1,0) -> 0 | T11: =IF(D11="Airport",1,0) -> 1
A12: STR-1003 | B12: 45717 | C12: North | D12: Airport | E12: 34285.21 | F12: 9172 | G12: 0.213 | H12: 22 | I12: 88.3 | J12: 10.46 | K12: 1 | L12: 3.8 | M12: 723060.76 | N12: 123131.24 | O12: =IF(C12="North",1,0) -> 1 | P12: =IF(C12="South",1,0) -> 0 | Q12: =IF(C12="East",1,0) -> 0 | R12: =IF(D12="Mall",1,0) -> 0 | S12: =IF(D12="High Street",1,0) -> 0 | T12: =IF(D12="Airport",1,0) -> 1
A13: STR-1003 | B13: 45748 | C13: North | D13: Airport | E13: 67979.88 | F13: 11230 | G13: 0.002 | H13: 28 | I13: 85.3 | J13: 7.16 | K13: 0 | L13: 3.8 | M13: 910791.94 | N13: 158891.28 | O13: =IF(C13="North",1,0) -> 1 | P13: =IF(C13="South",1,0) -> 0 | Q13: =IF(C13="East",1,0) -> 0 | R13: =IF(D13="Mall",1,0) -> 0 | S13: =IF(D13="High Street",1,0) -> 0 | T13: =IF(D13="Airport",1,0) -> 1
... A321: STR-1080 | B321: 45748 | C321: East | D321: Residential | E321: 40553.11 | F321: 5317 | G321: 0.165 | H321: 17 | I321: 84.3 | J321: 11.82 | K321: 0 | L321: 4.1 | M321: 559660.84 | N321: 71443.61 | O321: =IF(C321="North",1,0) -> 0 | P321: =IF(C321="South",1,0) -> 0 | Q321: =IF(C321="East",1,0) -> 1 | R321: =IF(D321="Mall",1,0) -> 0 | S321: =IF(D321="High Street",1,0) -> 0 | T321: =IF(D321="Airport",1,0) -> 0

Sheet Simple Regression
A1: SIMPLE REGRESSION SUMMARY #1: USING Marketing Spend
A3: Regression Statistics
A4: Multiple R | B4: 0.40895561
A5: R Square | B5: 0.16724469
A6: Adjusted R Square | B6: 0.16462596
A7: Standard Error | B7: 94846.034
A8: Observations | B8: 320
A10: ANOVA
B11: df | C11: SS | D11: MS | E11: F | F11: Significance F
A12: Regression | B12: 1 | C12: 5.7451371e+11 | D12: 5.7451371e+11 | E12: 63.864873 | F12: 2.4800615e-14
A13: Residual | B13: 318 | C13: 2.8606549e+12 | D13: 8.9957701e+09
A14: Total | B14: 319 | C14: 3.4351686e+12
B16: Coefficients | C16: Standard Error | D16: t Stat | E16: P-value | F16: Lower 95% | G16: Upper 95% | H16: Lower 95.0% | I16: Upper 95.0%
A17: Intercept | B17: 560777.35 | C17: 15906.906 | D17: 35.253703 | E17: 6.9528769e-112 | F17: 529481.27 | G17: 592073.42 | H17: 529481.27 | I17: 592073.42
A18: Marketing Spend | B18: 2.1295753 | C18: 0.26647838 | D18: 7.9915501 | E18: 2.4800615e-14 | F18: 1.6052919 | G18: 2.6538587 | H18: 1.6052919 | I18: 2.6538587
A21: Regression Equation: | B21: Monthly Sales = 560777.345 + (2.13 × Marketing Spend)
A22: R-Squared | B22: 0.16724469
A23: Coefficient | B23: 2.1295
A24: P-Value | B24: 2.4800615e-14

Sheet Simple Regresssion_Footfall
A1: SUMMARY OUTPUT: SIMPLE REGRESSION FOOTFALL
A3: Regression Statistics
A4: Multiple R | B4: 0.85807071
A5: R Square | B5: 0.73628534
A6: Adjusted R Square | B6: 0.73545605
A7: Standard Error | B7: 53373.736
A8: Observations | B8: 320
A10: ANOVA
B11: df | C11: SS | D11: MS | E11: F | F11: Significance F
A12: Regression | B12: 1 | C12: 2.5292643e+12 | D12: 2.5292643e+12 | E12: 887.84878 | F12: 4.7503615e-94
A13: Residual | B13: 318 | C13: 9.0590432e+11 | D13: 2.8487557e+09
A14: Total | B14: 319 | C14: 3.4351686e+12
B16: Coefficients | C16: Standard Error | D16: t Stat | E16: P-value | F16: Lower 95% | G16: Upper 95% | H16: Lower 95.0% | I16: Upper 95.0%
A17: Intercept | B17: 446410.58 | C17: 8407.7383 | D17: 53.095205 | E17: 4.0862696e-160 | F17: 429868.76 | G17: 462952.4 | H17: 429868.76 | I17: 462952.4
A18: footfall | B18: 35.678031 | C18: 1.1973783 | D18: 29.796791 | E18: 4.7503615e-94 | F18: 33.322247 | G18: 38.033815 | H18: 33.322247 | I18: 38.033815
A21: Regression Equation: | B21: Monthly Sales = 446410.58 + (35.678 × Marketing Spend)
A22: R-Squared | B22: 0.73628534
A23: Coefficient | B23: 35.678
A24: P-Value | B24: 4.0862696e-160

Sheet Multiple Regression

Sheet Predictions Residuals

Sheet Model Comparison

Sheet data_dictionary
A1: Column | B1: Description
A2: store_id | B2: Unique store identifier.
A3: month | B3: Reporting month.
A4: region | B4: Business region.
A5: store_type | B5: Mall, High Street, Residential, or Airport.
A6: marketing_spend | B6: Monthly marketing spend for the store.
A7: footfall | B7: Monthly visitor count.
A8: avg_discount_pct | B8: Average discount percentage for the month.
A9: staff_count | B9: Number of store staff.
A10: inventory_availability_pct | B10: Average product availability percentage.
A11: competitor_distance_km | B11: Distance to nearest competitor.
A12: holiday_flag | B12: 1 if the month/store period had a meaningful holiday effect; otherwise 0.
... A15: monthly_profit | B15: Optional secondary business metric.
